Workbook

Sheet МХК
C1: КАССА за период: | D1: 46023 | E1: 46387 | G1: МХК Шымкент | K1: =D1 -> 46023
C3: Остаток на начало дня | D3: =J4 -> 1662 | E3: Х | J3: =SUMPRODUCT(((МХК!$B$9:$B712)>=($J$1))*((МХК!$B$9:$B712)<($K$1))*(МХК!$D$9:$D712)) -> 1662 | K3: =SUMPRODUCT(((МХК!$B$9:$B712)>=($J$1))*((МХК!$B$9:$B712)<($K$1))*(МХК!$E$9:$E712)) -> 0
C4: Итого за | D4: =SUMPRODUCT(((МХК!$B$9:$B712)>=($D$1))*((МХК!$B$9:$B712)<=($E$1))*(МХК!$D$9:$D712)) -> 1689876 | E4: =SUMPRODUCT(((МХК!$B$9:$B712)>=($D$1))*((МХК!$B$9:$B712)<=($E$1))*(МХК!$E$9:$E712)) -> 1419515 | J4: =J3-K3 -> 1662
C5: Остаток на конец дня | D5: =D3+D4-E4 -> 272023
D7: Наличные деньги
A8: № п/п | B8: Дата | C8: Категория | D8: Приход | E8: Расход | F8: Безнал/Банк карта | G8: Коментарии | H8: Входит в указанный период
A9: 1 | B9: 46022 | C9: НАЧАЛЬНЫЙ ОСТАТОК | D9: 1662 | H9: =IF(AND(МХК!$B9>=$D$1,МХК!$B9<=$E$1),"V","") | K9: =IFERROR(__xludf.DUMMYFUNCTION("SORT(UNIQUE(C9:C1112))"),"Инкассация в БЦК") -> Инкассация в БЦК
A10: 2 | B10: 46027 | C10: ИП Юлдашев QR | F10: 38480
A11: 3 | B11: 46027 | C11: ИП Абдурахманова ГТ QR | F11: 13000
A12: 4 | B12: 46027 | C12: Физ лицо Интернет Магазин QR | F12: 3540
A13: 5 | B13: 46027 | C13: Физ лицо Интернет Магазин QR | F13: 6500
A14: 6 | B14: 46027 | C14: Физ лицо Интернет Магазин QR | F14: 3300
A15: 7 | B15: 46027 | C15: ИП Анартаева QR | F15: 51300
A16: 8 | B16: 46027 | C16: ИП Анартаева QR | F16: 179880
A17: 9 | B17: 46031 | C17: ТОО SENIM - AL | D17: 32720
A18: 10 | B18: 46031 | C18: заправка и покупка катриджа | E18: 10400
A19: 11 | B19: 46034 | C19: Физ лицо Интернет Магазин QR | F19: 19990 | G19: нак 13
A20: 12 | B20: 46034 | C20: Физ лицо Интернет Магазин QR | F20: 1990 | G20: нак 14
A21: 13 | B21: 46034 | C21: Физ лицо Интернет Магазин QR | F21: 7200 | G21: накл 21
A22: 14 | B22: 46034 | C22: ТОО ANADOLU MED | D22: 34290
A23: 15 | B23: 46034 | C23: ИП Мирсалиев QR | F23: 20400 | G23: нак 16
A24: 16 | B24: 46034 | C24: Физ лицо Интернет Магазин QR | F24: 3200 | G24: нак 67
A25: 17 | B25: 46034 | C25: Физ лицо Интернет Магазин QR | F25: 15200 | G25: нак 66
A26: 18 | B26: 46034 | C26: Физ лицо Интернет Магазин QR | F26: 21500 | G26: нак 95
A27: 19 | B27: 46034 | C27: ИП Абдурахманова | F27: 29200 | G27: старая накл 4865
A28: 20 | B28: 46034 | C28: Физ лицо Интернет Магазин QR | F28: 7200 | G28: нак 96
A29: 21 | B29: 46034 | C29: Физ лицо Интернет Магазин QR | F29: 15990 | G29: нак 97
A30: 22 | B30: 46034 | C30: Физ лицо Интернет Магазин QR | F30: 9700 | G30: нак104
A31: 23 | B31: 46034 | C31: Физ лицо Интернет Магазин QR | F31: 15990 | G31: накл105
A32: 24 | B32: 46034 | C32: Физ лицо сотрудник QR | F32: 7121 | G32: накл106
A33: 25 | B33: 46034 | C33: Физ лицо сотрудник QR | F33: 991 | G33: накл 107
A34: 26 | B34: 46034 | C34: ТОО Asyl pharm | F34: 49980 | G34: накл 5431 старая
... A47: 39 | B47: 46036 | C47: ТОО Анар медикал QR | F47: 23720 | G47: накл 112
A48: 40 | B48: 46036 | C48: ТОО Қыран | D48: 19990
A49: 41 | B49: 46036 | C49: ТОО INCOMED QR | F49: 128300 | G49: накл 5714
A50: 42 | B50: 46036 | C50: ИП Тажимаметова QR | F50: 44000 | G50: накл 5712
A51: 43 | B51: 46036 | C51: Физ лицо Интернет Магазин QR | F51: 15680 | G51: накл 135
A52: 44 | B52: 46036 | C52: ИП Мир здоровья QR | F52: 123530 | G52: накл 90
A53: 45 | B53: 46037 | C53: ТОО Аршат фарм QR | F53: 30530 | G53: накл 109
A54: 46 | B54: 46037 | C54: Физ лицо Интернет Магазин QR | F54: 7200 | G54: sem 159
...

Sheet Лист16

Sheet Справ.Номенк
A1: Штрих-код | B1: Артикул | C1: Краткое наименование | D1: Полное наименование | E1: Ед. изм. | F1: Код
A2: =IFERROR(__xludf.DUMMYFUNCTION("IMPORTRANGE(""1qptHSRGmBGpZ2a-3Sl03VuQVlQVTlolfenhhSjzQQ7U/edit#gid=490982906"",""Справ.Номенк!A2:H"")"),"ABENA") -> ABENA
A3: =IFERROR(__xludf.DUMMYFUNCTION("""COMPUTED_VALUE"""),5703538923937) -> 5703538923937 | B3: =IFERROR(__xludf.DUMMYFUNCTION("""COMPUTED_VALUE"""),254119) -> 254119 | C3: =IFERROR(__xludf.DUMMYFUNCTION("""COMPUTED_VALUE"""),"Abri-soft Underpads Superdry 60*60 (60 шт)") -> Abri-soft Underpads Superdry 60*60 (60 шт) | D3: =IFERROR(__xludf.DUMMYFUNCTION("""COMPUTED_VALUE"""),"Пеленки для взрослых одноразовые впитывающие Abri-soft Underpads Superdry 60*60 60 штук в упаковке ш/к 5703538923937") -> Пеленки для взрослых одноразовые впитывающие Abri-soft Underpads Superdry 60*60 60 штук в упаковке ш/к 5703538923937 | E3: =IFERROR(__xludf.DUMMYFUNCTION("""COMPUTED_VALUE"""),"шт") -> шт | F3: =IFERROR(__xludf.DUMMYFUNCTION("""COMPUTED_VALUE"""),77000000591) -> 77000000591 | G3: =IFERROR(__xludf.DUMMYFUNCTION("""COMPUTED_VALUE"""),5703538923937) -> 5703538923937
A4: =IFERROR(__xludf.DUMMYFUNCTION("""COMPUTED_VALUE"""),77336) -> 77336 | B4: =IFERROR(__xludf.DUMMYFUNCTION("""COMPUTED_VALUE"""),"254119_ШТ") -> 254119_ШТ | C4: =IFERROR(__xludf.DUMMYFUNCTION("""COMPUTED_VALUE"""),"Abri-soft Underpads Superdry 60*60 поштучно") -> Abri-soft Underpads Superdry 60*60 поштучно | D4: =IFERROR(__xludf.DUMMYFUNCTION("""COMPUTED_VALUE"""),"Пеленки для взрослых одноразовые впитывающие Abri-soft Underpads Superdry 60*60 поштучно") -> Пеленки для взрослых одноразовые впитывающие Abri-soft Underpads Superdry 60*60 поштучно | E4: =IFERROR(__xludf.DUMMYFUNCTION("""COMPUTED_VALUE"""),"шт") -> шт | F4: =IFERROR(__xludf.DUMMYFUNCTION("""COMPUTED_VALUE"""),"AST00000339") -> AST00000339 | G4: =IFERROR(__xludf.DUMMYFUNCTION("""COMPUTED_VALUE"""),77336) -> 77336
A5: =IFERROR(__xludf.DUMMYFUNCTION("""COMPUTED_VALUE"""),5703538924019) -> 5703538924019 | B5: =IFERROR(__xludf.DUMMYFUNCTION("""COMPUTED_VALUE"""),254123) -> 254123 | C5: =IFERROR(__xludf.DUMMYFUNCTION("""COMPUTED_VALUE"""),"Abri-soft Underpads Superdry 60*90 (30 шт)") -> Abri-soft Underpads Superdry 60*90 (30 шт) | D5: =IFERROR(__xludf.DUMMYFUNCTION("""COMPUTED_VALUE"""),"Пеленки для взрослых одноразовые впитывающие Abri-soft Underpads Superdry 60*90 30 штук в упаковке ш/к 5703538924019") -> Пеленки для взрослых одноразовые впитывающие Abri-soft Underpads Superdry 60*90 30 штук в упаковке ш/к 5703538924019 | E5: =IFERROR(__xludf.DUMMYFUNCTION("""COMPUTED_VALUE"""),"шт") -> шт | F5: =IFERROR(__xludf.DUMMYFUNCTION("""COMPUTED_VALUE"""),77000000592) -> 77000000592 | G5: =IFERROR(__xludf.DUMMYFUNCTION("""COMPUTED_VALUE"""),5703538924019) -> 5703538924019
A6: =IFERROR(__xludf.DUMMYFUNCTION("""COMPUTED_VALUE"""),5710811037175) -> 5710811037175 | B6: =IFERROR(__xludf.DUMMYFUNCTION("""COMPUTED_VALUE"""),4107410) -> 4107410 | C6: =IFERROR(__xludf.DUMMYFUNCTION("""COMPUTED_VALUE"""),"Abri-flex М1 Premium (14 шт)") -> Abri-flex М1 Premium (14 шт) | D6: =IFERROR(__xludf.DUMMYFUNCTION("""COMPUTED_VALUE"""),"Подгузники одноразовые для взрослых Abri-flex М1 Premium 14 штук в упаковке ш/к 5710811037175") -> Подгузники одноразовые для взрослых Abri-flex М1 Premium 14 штук в упаковке ш/к 5710811037175 | E6: =IFERROR(__xludf.DUMMYFUNCTION("""COMPUTED_VALUE"""),"шт") -> шт | F6: =IFERROR(__xludf.DUMMYFUNCTION("""COMPUTED_VALUE"""),77000000589) -> 77000000589 | G6: =IFERROR(__xludf.DUMMYFUNCTION("""COMPUTED_VALUE"""),5710811037175) -> 5710811037175
A7: =IFERROR(__xludf.DUMMYFUNCTION("""COMPUTED_VALUE"""),5710811037328) -> 5710811037328 | B7: =IFERROR(__xludf.DUMMYFUNCTION("""COMPUTED_VALUE"""),4107710) -> 4107710 | C7: =IFERROR(__xludf.DUMMYFUNCTION("""COMPUTED_VALUE"""),"Abri-flex L1 Premium (14 шт)") -> Abri-flex L1 Premium (14 шт) | D7: =IFERROR(__xludf.DUMMYFUNCTION("""COMPUTED_VALUE"""),"Подгузники одноразовые для взрослых Abri-flex L1 Premium 14 штук в упаковке ш/к 5710811037328") -> Подгузники одноразовые для взрослых Abri-flex L1 Premium 14 штук в упаковке ш/к 5710811037328 | E7: =IFERROR(__xludf.DUMMYFUNCTION("""COMPUTED_VALUE"""),"шт") -> шт | F7: =IFERROR(__xludf.DUMMYFUNCTION("""COMPUTED_VALUE"""),77000000590) -> 77000000590 | G7: =IFERROR(__xludf.DUMMYFUNCTION("""COMPUTED_VALUE"""),5710811037328) -> 5710811037328
A8: =IFERROR(__xludf.DUMMYFUNCTION("""COMPUTED_VALUE"""),5703538759734) -> 5703538759734 | B8: =IFERROR(__xludf.DUMMYFUNCTION("""COMPUTED_VALUE"""),4305501) -> 4305501 | C8: =IFERROR(__xludf.DUMMYFUNCTION("""COMPUTED_VALUE"""),"Abri-form S2 Premium (28 шт)") -> Abri-form S2 Premium (28 шт) | D8: =IFERROR(__xludf.DUMMYFUNCTION("""COMPUTED_VALUE"""),"Подгузники одноразовые для взрослых Abri-form S2 Premium 28 штук в упаковке ш/к 5703538759734") -> Подгузники одноразовые для взрослых Abri-form S2 Premium 28 штук в упаковке ш/к 5703538759734 | E8: =IFERROR(__xludf.DUMMYFUNCTION("""COMPUTED_VALUE"""),"шт") -> шт | F8: =IFERROR(__xludf.DUMMYFUNCTION("""COMPUTED_VALUE"""),77000000581) -> 77000000581 | G8: =IFERROR(__xludf.DUMMYFUNCTION("""COMPUTED_VALUE"""),5703538759734) -> 5703538759734
A9: =IFERROR(__xludf.DUMMYFUNCTION("""COMPUTED_VALUE"""),77384) -> 77384 | B9: =IFERROR(__xludf.DUMMYFUNCTION("""COMPUTED_VALUE"""),"4305501_ШТ") -> 4305501_ШТ | C9: =IFERROR(__xludf.DUMMYFUNCTION("""COMPUTED_VALUE"""),"Abri-form S2 Premium (1 шт) поштучно") -> Abri-form S2 Premium (1 шт) поштучно | D9: =IFERROR(__xludf.DUMMYFUNCTION("""COMPUTED_VALUE"""),"Подгузники одноразовые для взрослых Abri-form S2 Premium (поштучно)") -> Подгузники одноразовые для взрослых Abri-form S2 Premium (поштучно) | E9: =IFERROR(__xludf.DUMMYFUNCTION("""COMPUTED_VALUE"""),"шт") -> шт | F9: =IFERROR(__xludf.DUMMYFUNCTION("""COMPUTED_VALUE"""),"AST00000369") -> AST00000369 | G9: =IFERROR(__xludf.DUMMYFUNCTION("""COMPUTED_VALUE"""),77384) -> 77384
A10: =IFERROR(__xludf.DUMMYFUNCTION("""COMPUTED_VALUE"""),5703538759536) -> 5703538759536 | B10: =IFERROR(__xludf.DUMMYFUNCTION("""COMPUTED_VALUE"""),4306101) -> 4306101 | C10: =IFERROR(__xludf.DUMMYFUNCTION("""COMPUTED_VALUE"""),"Abri-form М1 Premium (26 шт)") -> Abri-form М1 Premium (26 шт) | D10: =IFERROR(__xludf.DUMMYFUNCTION("""COMPUTED_VALUE"""),"Подгузники одноразовые для взрослых Abri-form М1 Premium 26 штук в упаковке ш/к 5703538759536") -> Подгузники одноразовые для взрослых Abri-form М1 Premium 26 штук в упаковке ш/к 5703538759536 | E10: =IFERROR(__xludf.DUMMYFUNCTION("""COMPUTED_VALUE"""),"шт") -> шт | F10: =IFERROR(__xludf.DUMMYFUNCTION("""COMPUTED_VALUE"""),77000000582) -> 77000000582 | G10: =IFERROR(__xludf.DUMMYFUNCTION("""COMPUTED_VALUE"""),5703538759536) -> 5703538759536
A11: =IFERROR(__xludf.DUMMYFUNCTION("""COMPUTED_VALUE"""),5703538759574) -> 5703538759574 | B11: =IFERROR(__xludf.DUMMYFUNCTION("""COMPUTED_VALUE"""),4306201) -> 4306201 | C11: =IFERROR(__xludf.DUMMYFUNCTION("""COMPUTED_VALUE"""),"Abri-form М3 Premium (22 шт)") -> Abri-form М3 Premium (22 шт) | D11: =IFERROR(__xludf.DUMMYFUNCTION("""COMPUTED_VALUE"""),"Подгузники одноразовые для взрослых Abri-form М3 Premium 22 штук в упаковке ш/к 5703538759574") -> Подгузники одноразовые для взрослых Abri-form М3 Premium 22 штук в упаковке ш/к 5703538759574 | E11: =IFERROR(__xludf.DUMMYFUNCTION("""COMPUTED_VALUE"""),"шт") -> шт | F11: =IFERROR(__xludf.DUMMYFUNCTION("""COMPUTED_VALUE"""),77000000583) -> 77000000583 | G11: =IFERROR(__xludf.DUMMYFUNCTION("""COMPUTED_VALUE"""),5703538759574) -> 5703538759574
A12: =IFERROR(__xludf.DUMMYFUNCTION("""COMPUTED_VALUE"""),5703538759659) -> 5703538759659 | B12: =IFERROR(__xludf.DUMMYFUNCTION("""COMPUTED_VALUE"""),4306601) -> 4306601 | C12: =IFERROR(__xludf.DUMMYFUNCTION("""COMPUTED_VALUE"""),"Abri-form L1 Premium (26 шт)") -> Abri-form L1 Premium (26 шт) | D12: =IFERROR(__xludf.DUMMYFUNCTION("""COMPUTED_VALUE"""),"Подгузники одноразовые для взрослых Abri-form L1 Premium 26 штук в упаковке ш/к 5703538759659") -> Подгузники одноразовые для взрослых Abri-form L1 Premium 26 штук в упаковке ш/к 5703538759659 | E12: =IFERROR(__xludf.DUMMYFUNCTION("""COMPUTED_VALUE"""),"шт") -> шт | F12: =IFERROR(__xludf.DUMMYFUNCTION("""COMPUTED_VALUE"""),77000000584) -> 77000000584 | G12: =IFERROR(__xludf.DUMMYFUNCTION("""COMPUTED_VALUE"""),5703538759659) -> 5703538759659
A13: =IFERROR(__xludf.DUMMYFUNCTION("""COMPUTED_VALUE"""),5703538759819) -> 5703538759819 | B13: =IFERROR(__xludf.DUMMYFUNCTION("""COMPUTED_VALUE"""),4306701) -> 4306701 | C13: =IFERROR(__xludf.DUMMYFUNCTION("""COMPUTED_VALUE"""),"Abri-form L3 Premium (20 шт)") -> Abri-form L3 Premium (20 шт) | D13: =IFERROR(__xludf.DUMMYFUNCTION("""COMPUTED_VALUE"""),"Подгузники одноразовые для взрослых Abri-form L3 Premium 20 штук в упаковке ш/к 5703538759819") -> Подгузники одноразовые для взрослых Abri-form L3 Premium 20 штук в упаковке ш/к 5703538759819 | E13: =IFERROR(__xludf.DUMMYFUNCTION("""COMPUTED_VALUE"""),"шт") -> шт | F13: =IFERROR(__xludf.DUMMYFUNCTION("""COMPUTED_VALUE"""),77000000585) -> 77000000585 | G13: =IFERROR(__xludf.DUMMYFUNCTION("""COMPUTED_VALUE"""),5703538759819) -> 5703538759819
A14: =IFERROR(__xludf.DUMMYFUNCTION("""COMPUTED_VALUE"""),5703538700491) -> 5703538700491 | B14: =IFERROR(__xludf.DUMMYFUNCTION("""COMPUTED_VALUE"""),473505) -> 473505 | C14: =IFERROR(__xludf.DUMMYFUNCTION("""COMPUTED_VALUE"""),"Abri-form L1 Premium (10 шт)") -> Abri-form L1 Premium (10 шт) | D14: =IFERROR(__xludf.DUMMYFUNCTION("""COMPUTED_VALUE"""),"Подгузники одноразовые для взрослых Abri-form L1 Premium (10 штук в упаковке) ш/к 5703538700491") -> Подгузники одноразовые для взрослых Abri-form L1 Premium (10 штук в упаковке) ш/к 5703538700491 | E14: =IFERROR(__xludf.DUMMYFUNCTION("""COMPUTED_VALUE"""),"шт") -> шт | F14: =IFERROR(__xludf.DUMMYFUNCTION("""COMPUTED_VALUE"""),77000000586) -> 77000000586 | G14: =IFERROR(__xludf.DUMMYFUNCTION("""COMPUTED_VALUE"""),5703538700491) -> 5703538700491 | H14: =IFERROR(__xludf.DUMMYFUNCTION("""COMPUTED_VALUE"""),"M/L") -> M/L
A15: =IFERROR(__xludf.DUMMYFUNCTION("""COMPUTED_VALUE"""),5703538700453) -> 5703538700453 | B15: =IFERROR(__xludf.DUMMYFUNCTION("""COMPUTED_VALUE"""),474005) -> 474005 | C15: =IFERROR(__xludf.DUMMYFUNCTION("""COMPUTED_VALUE"""),"Abri-form М2 Premium (10 шт)") -> Abri-form М2 Premium (10 шт) | D15: =IFERROR(__xludf.DUMMYFUNCTION("""COMPUTED_VALUE"""),"Подгузники одноразовые для взрослых Abri-form М2 Premium (10 штук в упаковке) ш/к 5703538700453") -> Подгузники одноразовые для взрослых Abri-form М2 Premium (10 штук в упаковке) ш/к 5703538700453 | E15: =IFERROR(__xludf.DUMMYFUNCTION("""COMPUTED_VALUE"""),"шт") -> шт | F15: =IFERROR(__xludf.DUMMYFUNCTION("""COMPUTED_VALUE"""),77000000587) -> 77000000587 | G15: =IFERROR(__xludf.DUMMYFUNCTION("""COMPUTED_VALUE"""),5703538700453) -> 5703538700453 | H15: =IFERROR(__xludf.DUMMYFUNCTION("""COMPUTED_VALUE"""),"XL/XXL") -> XL/XXL
A16: =IFERROR(__xludf.DUMMYFUNCTION("""COMPUTED_VALUE"""),5703538700538) -> 5703538700538 | B16: =IFERROR(__xludf.DUMMYFUNCTION("""COMPUTED_VALUE"""),474505) -> 474505 | C16: =IFERROR(__xludf.DUMMYFUNCTION("""COMPUTED_VALUE"""),"Abri-form L2 Premium (10 шт)") -> Abri-form L2 Premium (10 шт) | D16: =IFERROR(__xludf.DUMMYFUNCTION("""COMPUTED_VALUE"""),"Подгузники одноразовые для взрослых Abri-form L2 Premium (10 штук в упаковке) ш/к 5703538700538") -> Подгузники одноразовые для взрослых Abri-form L2 Premium (10 штук в упаковке) ш/к 5703538700538 | E16: =IFERROR(__xludf.DUMMYFUNCTION("""COMPUTED_VALUE"""),"шт") -> шт | F16: =IFERROR(__xludf.DUMMYFUNCTION("""COMPUTED_VALUE"""),77000000588) -> 77000000588 | G16: =IFERROR(__xludf.DUMMYFUNCTION("""COMPUTED_VALUE"""),5703538700538) -> 5703538700538 | H16: =IFERROR(__xludf.DUMMYFUNCTION("""COMPUTED_VALUE"""),"XS/S") -> XS/S
A17: =IFERROR(__xludf.DUMMYFUNCTION("""COMPUTED_VALUE"""),77375) -> 77375 | B17: =IFERROR(__xludf.DUMMYFUNCTION("""COMPUTED_VALUE"""),"474505_ШТ") -> 474505_ШТ | C17: =IFERROR(__xludf.DUMMYFUNCTION("""COMPUTED_VALUE"""),"Abri-form L2 Premium (1 шт) поштучно") -> Abri-form L2 Premium (1 шт) поштучно | D17: =IFERROR(__xludf.DUMMYFUNCTION("""COMPUTED_VALUE"""),"Подгузники одноразовые для взрослых Abri-form L2 Premium (поштучно)") -> Подгузники одноразовые для взрослых Abri-form L2 Premium (поштучно) | E17: =IFERROR(__xludf.DUMMYFUNCTION("""COMPUTED_VALUE"""),"шт") -> шт | F17: =IFERROR(__xludf.DUMMYFUNCTION("""COMPUTED_VALUE"""),"AST00000345") -> AST00000345 | G17: =IFERROR(__xludf.DUMMYFUNCTION("""COMPUTED_VALUE"""),77375) -> 77375 | H17: =IFERROR(__xludf.DUMMYFUNCTION("""COMPUTED_VALUE"""),"L") -> L
A18: =IFERROR(__xludf.DUMMYFUNCTION("""COMPUTED_VALUE"""),"Dr.Frei Гигеническая маска") -> Dr.Frei Гигеническая маска | H18: =IFERROR(__xludf.DUMMYFUNCTION("""COMPUTED_VALUE"""),"S") -> S
A19: =IFERROR(__xludf.DUMMYFUNCTION("""COMPUTED_VALUE"""),3800232484541) -> 3800232484541 | B19: =IFERROR(__xludf.DUMMYFUNCTION("""COMPUTED_VALUE"""),"0300338 L/X бежевый") -> 0300338 L/X бежевый | C19: =IFERROR(__xludf.DUMMYFUNCTION("""COMPUTED_VALUE"""),"М 0201 L/XL/M Гигиеническая маска, бежевая") -> М 0201 L/XL/M Гигиеническая маска, бежевая | D19: =IFERROR(__xludf.DUMMYFUNCTION("""COMPUTED_VALUE"""),"М 0201 L/XL/M Гигиеническая маска, бежевая ш/к 3800232484541") -> М 0201 L/XL/M Гигиеническая маска, бежевая ш/к 3800232484541 | E19: =IFERROR(__xludf.DUMMYFUNCTION("""COMPUTED_VALUE"""),"шт") -> шт | F19: =IFERROR(__xludf.DUMMYFUNCTION("""COMPUTED_VALUE"""),"AST00000613") -> AST00000613 | G19: =IFERROR(__xludf.DUMMYFUNCTION("""COMPUTED_VALUE"""),3800232484541) -> 3800232484541 | H19: =IFERROR(__xludf.DUMMYFUNCTION("""COMPUTED_VALUE"""),"XL") -> XL
A20: =IFERROR(__xludf.DUMMYFUNCTION("""COMPUTED_VALUE"""),3800232484534) -> 3800232484534 | B20: =IFERROR(__xludf.DUMMYFUNCTION("""COMPUTED_VALUE"""),"0300338 XS/M бежевый") -> 0300338 XS/M бежевый | C20: =IFERROR(__xludf.DUMMYFUNCTION("""COMPUTED_VALUE"""),"М 0201 XS/M Гигиеническая маска, бежевая") -> М 0201 XS/M Гигиеническая маска, бежевая | D20: =IFERROR(__xludf.DUMMYFUNCTION("""COMPUTED_VALUE"""),"М 0201 XS/M Гигиеническая маска, бежевая ш/к 3800232484534") -> М 0201 XS/M Гигиеническая маска, бежевая ш/к 3800232484534 | E20: =IFERROR(__xludf.DUMMYFUNCTION("""COMPUTED_VALUE"""),"шт") -> шт | F20: =IFERROR(__xludf.DUMMYFUNCTION("""COMPUTED_VALUE"""),"AST00000612") -> AST00000612 | G20: =IFERROR(__xludf.DUMMYFUNCTION("""COMPUTED_VALUE"""),3800232484534) -> 3800232484534 | H20: =IFERROR(__xludf.DUMMYFUNCTION("""COMPUTED_VALUE"""),"XXL") -> XXL
A21: =IFERROR(__xludf.DUMMYFUNCTION("""COMPUTED_VALUE"""),3800232484657) -> 3800232484657 | B21: =IFERROR(__xludf.DUMMYFUNCTION("""COMPUTED_VALUE"""),"0300339 L/XL черный") -> 0300339 L/XL черный | C21: =IFERROR(__xludf.DUMMYFUNCTION("""COMPUTED_VALUE"""),"М 0201 L/XL Гигеническая маска, черная") -> М 0201 L/XL Гигеническая маска, черная | D21: =IFERROR(__xludf.DUMMYFUNCTION("""COMPUTED_VALUE"""),"М 0201 L/XL Гигеническая маска, черная ш/к 3800232484657") -> М 0201 L/XL Гигеническая маска, черная ш/к 3800232484657 | E21: =IFERROR(__xludf.DUMMYFUNCTION("""COMPUTED_VALUE"""),"шт") -> шт | F21: =IFERROR(__xludf.DUMMYFUNCTION("""COMPUTED_VALUE"""),"AST00000611") -> AST00000611 | G21: =IFERROR(__xludf.DUMMYFUNCTION("""COMPUTED_VALUE"""),3800232484657) -> 3800232484657 | H21: =IFERROR(__xludf.DUMMYFUNCTION("""COMPUTED_VALUE"""),"XXXL") -> XXXL
A22: =IFERROR(__xludf.DUMMYFUNCTION("""COMPUTED_VALUE"""),3800232484640) -> 3800232484640 | B22: =IFERROR(__xludf.DUMMYFUNCTION("""COMPUTED_VALUE"""),"0300339 XS/M черный") -> 0300339 XS/M черный | C22: =IFERROR(__xludf.DUMMYFUNCTION("""COMPUTED_VALUE"""),"М 0201 XS/M Гигеническая маска, черная") -> М 0201 XS/M Гигеническая маска, черная | D22: =IFERROR(__xludf.DUMMYFUNCTION("""COMPUTED_VALUE"""),"М 0201 XS/M Гигеническая маска, черная ш/к 3800232484640") -> М 0201 XS/M Гигеническая маска, черная ш/к 3800232484640 | E22: =IFERROR(__xludf.DUMMYFUNCTION("""COMPUTED_VALUE"""),"шт") -> шт | F22: =IFERROR(__xludf.DUMMYFUNCTION("""COMPUTED_VALUE"""),"AST00000610") -> AST00000610 | G22: =IFERROR(__xludf.DUMMYFUNCTION("""COMPUTED_VALUE"""),3800232484640) -> 3800232484640 | H22: =IFERROR(__xludf.DUMMYFUNCTION("""COMPUTED_VALUE"""),"M") -> M
A23: =IFERROR(__xludf.DUMMYFUNCTION("""COMPUTED_VALUE"""),"Dr.Frei Медицинские пластыри") -> Dr.Frei Медицинские пластыри | H23: =IFERROR(__xludf.DUMMYFUNCTION("""COMPUTED_VALUE"""),"L") -> L
A24: =IFERROR(__xludf.DUMMYFUNCTION("""COMPUTED_VALUE"""),7640162323123) -> 7640162323123 | B24: =IFERROR(__xludf.DUMMYFUNCTION("""COMPUTED_VALUE"""),"КПНТО №20") -> КПНТО №20 | C24: =IFERROR(__xludf.DUMMYFUNCTION("""COMPUTED_VALUE"""),"КОМПЛЕКТ ПЛАСТЫРЕЙ НА ТКАНЕВОЙ ОСНОВЕ №20") -> КОМПЛЕКТ ПЛАСТЫРЕЙ НА ТКАНЕВОЙ ОСНОВЕ №20 | D24: =IFERROR(__xludf.DUMMYFUNCTION("""COMPUTED_VALUE"""),"КОМПЛЕКТ ПЛАСТЫРЕЙ НА ТКАНЕВОЙ ОСНОВЕ ТМ Dr.Frei №20 / ш/к 7640162323123") -> КОМПЛЕКТ ПЛАСТЫРЕЙ НА ТКАНЕВОЙ ОСНОВЕ ТМ Dr.Frei №20 / ш/к 7640162323123 | E24: =IFERROR(__xludf.DUMMYFUNCTION("""COMPUTED_VALUE"""),"шт") -> шт | F24: =IFERROR(__xludf.DUMMYFUNCTION("""COMPUTED_VALUE"""),"AST00000619") -> AST00000619 | G24: =IFERROR(__xludf.DUMMYFUNCTION("""COMPUTED_VALUE"""),7640162323123) -> 7640162323123 | H24: =IFERROR(__xludf.DUMMYFUNCTION("""COMPUTED_VALUE"""),"L") -> L
A25: =IFERROR(__xludf.DUMMYFUNCTION("""COMPUTED_VALUE"""),7640162323178) -> 7640162323178 | B25: =IFERROR(__xludf.DUMMYFUNCTION("""COMPUTED_VALUE"""),"МНП №10 19х72mm НЕТКАНЫЙ") -> МНП №10 19х72mm НЕТКАНЫЙ | C25: =IFERROR(__xludf.DUMMYFUNCTION("""COMPUTED_VALUE"""),"МЕДИЦИНСКИЙ НЕТКАНЫЙ ПЛАСТЫРЬ (19mm х 72mm) №10") -> МЕДИЦИНСКИЙ НЕТКАНЫЙ ПЛАСТЫРЬ (19mm х 72mm) №10 | D25: =IFERROR(__xludf.DUMMYFUNCTION("""COMPUTED_VALUE"""),"МЕДИЦИНСКИЙ НЕТКАНЫЙ ПЛАСТЫРЬ «TM Dr.Frei» №10, (19mm х 72mm) /ш/к 7640162323178") -> МЕДИЦИНСКИЙ НЕТКАНЫЙ ПЛАСТЫРЬ «TM Dr.Frei» №10, (19mm х 72mm) /ш/к 7640162323178 | E25: =IFERROR(__xludf.DUMMYFUNCTION("""COMPUTED_VALUE"""),"шт") -> шт | F25: =IFERROR(__xludf.DUMMYFUNCTION("""COMPUTED_VALUE"""),"AST00000616") -> AST00000616 | G25: =IFERROR(__xludf.DUMMYFUNCTION("""COMPUTED_VALUE"""),7640162323178) -> 7640162323178 | H25: =IFERROR(__xludf.DUMMYFUNCTION("""COMPUTED_VALUE"""),"M") -> M
A26: =IFERROR(__xludf.DUMMYFUNCTION("""COMPUTED_VALUE"""),7640162323185) -> 7640162323185 | B26: =IFERROR(__xludf.DUMMYFUNCTION("""COMPUTED_VALUE"""),"МНП №100 19х72mm НЕТКАНЫЙ") -> МНП №100 19х72mm НЕТКАНЫЙ | C26: =IFERROR(__xludf.DUMMYFUNCTION("""COMPUTED_VALUE"""),"МЕДИЦИНСКИЙ НЕТКАНЫЙ ПЛАСТЫРЬ (19mm х 72mm) №100") -> МЕДИЦИНСКИЙ НЕТКАНЫЙ ПЛАСТЫРЬ (19mm х 72mm) №100 | D26: =IFERROR(__xludf.DUMMYFUNCTION("""COMPUTED_VALUE"""),"МЕДИЦИНСКИЙ НЕТКАНЫЙ ПЛАСТЫРЬ «TM Dr.Frei» №100, (19mm х 72mm) /ш/к 7640162323185") -> МЕДИЦИНСКИЙ НЕТКАНЫЙ ПЛАСТЫРЬ «TM Dr.Frei» №100, (19mm х 72mm) /ш/к 7640162323185 | E26: =IFERROR(__xludf.DUMMYFUNCTION("""COMPUTED_VALUE"""),"шт") -> шт | F26: =IFERROR(__xludf.DUMMYFUNCTION("""COMPUTED_VALUE"""),"AST00000617") -> AST00000617 | G26: =IFERROR(__xludf.DUMMYFUNCTION("""COMPUTED_VALUE"""),7640162323185) -> 7640162323185 | H26: =IFERROR(__xludf.DUMMYFUNCTION("""COMPUTED_VALUE"""),"M") -> M
A27: =IFERROR(__xludf.DUMMYFUNCTION("""COMPUTED_VALUE"""),7640162323215) -> 7640162323215 | B27: =IFERROR(__xludf.DUMMYFUNCTION("""COMPUTED_VALUE"""),"МНПВР 5m x 1,25cm НЕТКАНЫ") -> МНПВР 5m x 1,25cm НЕТКАНЫ | C27: =IFERROR(__xludf.DUMMYFUNCTION("""COMPUTED_VALUE"""),"МЕДИЦИНСКИЙ НЕТКАНЫЙ ПЛАСТЫРЬ В РУЛОНЕ (5 м x 1,25cm)") -> МЕДИЦИНСКИЙ НЕТКАНЫЙ ПЛАСТЫРЬ В РУЛОНЕ (5 м x 1,25cm) | D27: =IFERROR(__xludf.DUMMYFUNCTION("""COMPUTED_VALUE"""),"МЕДИЦИНСКИЙ НЕТКАНЫЙ ПЛАСТЫРЬ В РУЛОНЕ «ТМ Dr.Frei» (5 м x 1,25см) / ш/к 7640162323215") -> МЕДИЦИНСКИЙ НЕТКАНЫЙ ПЛАСТЫРЬ В РУЛОНЕ «ТМ Dr.Frei» (5 м x 1,25см) / ш/к 7640162323215 | E27: =IFERROR(__xludf.DUMMYFUNCTION("""COMPUTED_VALUE"""),"шт") -> шт | F27: =IFERROR(__xludf.DUMMYFUNCTION("""COMPUTED_VALUE"""),"AST00000624") -> AST00000624 | G27: =IFERROR(__xludf.DUMMYFUNCTION("""COMPUTED_VALUE"""),7640162323215) -> 7640162323215 | H27: =IFERROR(__xludf.DUMMYFUNCTION("""COMPUTED_VALUE"""),"S") -> S
A28: =IFERROR(__xludf.DUMMYFUNCTION("""COMPUTED_VALUE"""),7640162323222) -> 7640162323222 | B28: =IFERROR(__xludf.DUMMYFUNCTION("""COMPUTED_VALUE"""),"МНПВР 5m x 2,5cm НЕТКАНЫЙ") -> МНПВР 5m x 2,5cm НЕТКАНЫЙ | C28: =IFERROR(__xludf.DUMMYFUNCTION("""COMPUTED_VALUE"""),"МЕДИЦИНСКИЙ НЕТКАНЫЙ ПЛАСТЫРЬ В РУЛОНЕ (5 м x 2,5cm)") -> МЕДИЦИНСКИЙ НЕТКАНЫЙ ПЛАСТЫРЬ В РУЛОНЕ (5 м x 2,5cm) | D28: =IFERROR(__xludf.DUMMYFUNCTION("""COMPUTED_VALUE"""),"МЕДИЦИНСКИЙ НЕТКАНЫЙ ПЛАСТЫРЬ В РУЛОНЕ «ТМ Dr.Frei» (5 м x 2,5см) / ш/к 7640162323222") -> МЕДИЦИНСКИЙ НЕТКАНЫЙ ПЛАСТЫРЬ В РУЛОНЕ «ТМ Dr.Frei» (5 м x 2,5см) / ш/к 7640162323222 | E28: =IFERROR(__xludf.DUMMYFUNCTION("""COMPUTED_VALUE"""),"шт") -> шт | F28: =IFERROR(__xludf.DUMMYFUNCTION("""COMPUTED_VALUE"""),"AST00000625") -> AST00000625 | G28: =IFERROR(__xludf.DUMMYFUNCTION("""COMPUTED_VALUE"""),7640162323222) -> 7640162323222 | H28: =IFERROR(__xludf.DUMMYFUNCTION("""COMPUTED_VALUE"""),"S") -> S
A29: =IFERROR(__xludf.DUMMYFUNCTION("""COMPUTED_VALUE"""),7640162323116) -> 7640162323116 | B29: =IFERROR(__xludf.DUMMYFUNCTION("""COMPUTED_VALUE"""),"МП №4") -> МП №4 | C29: =IFERROR(__xludf.DUMMYFUNCTION("""COMPUTED_VALUE"""),"МОЗОЛЬНЫЙ ПЛАСТЫРЬ (19mm х 72mm) №4") -> МОЗОЛЬНЫЙ ПЛАСТЫРЬ (19mm х 72mm) №4 | D29: =IFERROR(__xludf.DUMMYFUNCTION("""COMPUTED_VALUE"""),"МОЗОЛЬНЫЙ ПЛАСТЫРЬ ТМ Dr.Frei /ш/к 7640162323116") -> МОЗОЛЬНЫЙ ПЛАСТЫРЬ ТМ Dr.Frei /ш/к 7640162323116 | E29: =IFERROR(__xludf.DUMMYFUNCTION("""COMPUTED_VALUE"""),"шт") -> шт | F29: =IFERROR(__xludf.DUMMYFUNCTION("""COMPUTED_VALUE"""),"AST00000621") -> AST00000621 | G29: =IFERROR(__xludf.DUMMYFUNCTION("""COMPUTED_VALUE"""),7640162323116) -> 7640162323116 | H29: =IFERROR(__xludf.DUMMYFUNCTION("""COMPUTED_VALUE"""),"XL") -> XL
A30: =IFERROR(__xludf.DUMMYFUNCTION("""COMPUTED_VALUE"""),7640162323147) -> 7640162323147 | B30: =IFERROR(__xludf.DUMMYFUNCTION("""COMPUTED_VALUE"""),"МПННО №10 10х6сm НЕТКАНЫЙ") -> МПННО №10 10х6сm НЕТКАНЫЙ | C30: =IFERROR(__xludf.DUMMYFUNCTION("""COMPUTED_VALUE"""),"МЕДИЦИНСКИЙ ПЛАСТЫРЬ НА НЕТКАНОЙ ОСНОВЕ (10сm х 6сm) №10") -> МЕДИЦИНСКИЙ ПЛАСТЫРЬ НА НЕТКАНОЙ ОСНОВЕ (10сm х 6сm) №10 | D30: =IFERROR(__xludf.DUMMYFUNCTION("""COMPUTED_VALUE"""),"МЕДИЦИНСКИЙ ПЛАСТЫРЬ НА НЕТКАНОЙ ОСНОВЕ ТМ Dr.Frei №10 /ш/к 7640162323147") -> МЕДИЦИНСКИЙ ПЛАСТЫРЬ НА НЕТКАНОЙ ОСНОВЕ ТМ Dr.Frei №10 /ш/к 7640162323147 | E30: =IFERROR(__xludf.DUMMYFUNCTION("""COMPUTED_VALUE"""),"шт") -> шт | F30: =IFERROR(__xludf.DUMMYFUNCTION("""COMPUTED_VALUE"""),"AST00000618") -> AST00000618 | G30: =IFERROR(__xludf.DUMMYFUNCTION("""COMPUTED_VALUE"""),7640162323147) -> 7640162323147 | H30: =IFERROR(__xludf.DUMMYFUNCTION("""COMPUTED_VALUE"""),"XL") -> XL
A31: =IFERROR(__xludf.DUMMYFUNCTION("""COMPUTED_VALUE"""),7640162323154) -> 7640162323154 | B31: =IFERROR(__xludf.DUMMYFUNCTION("""COMPUTED_VALUE"""),"МПНТО №10 19х72mm ТКАНЕВЫ") -> МПНТО №10 19х72mm ТКАНЕВЫ | C31: =IFERROR(__xludf.DUMMYFUNCTION("""COMPUTED_VALUE"""),"МЕДИЦИНСКИЙ ПЛАСТЫРЬ НА ТКАНЕВОЙ ОСНОВЕ (19mm х 72mm) №10") -> МЕДИЦИНСКИЙ ПЛАСТЫРЬ НА ТКАНЕВОЙ ОСНОВЕ (19mm х 72mm) №10 | D31: =IFERROR(__xludf.DUMMYFUNCTION("""COMPUTED_VALUE"""),"МЕДИЦИНСКИЙ ПЛАСТЫРЬ НА ТКАНЕВОЙ ОСНОВЕ «ТМ Dr.Frei» №10 (19mm х 72mm) / ш/к 7640162323154") -> МЕДИЦИНСКИЙ ПЛАСТЫРЬ НА ТКАНЕВОЙ ОСНОВЕ «ТМ Dr.Frei» №10 (19mm х 72mm) / ш/к 7640162323154 | E31: =IFERROR(__xludf.DUMMYFUNCTION("""COMPUTED_VALUE"""),"шт") -> шт | F31: =IFERROR(__xludf.DUMMYFUNCTION("""COMPUTED_VALUE"""),"AST00000614") -> AST00000614 | G31: =IFERROR(__xludf.DUMMYFUNCTION("""COMPUTED_VALUE"""),7640162323154) -> 7640162323154 | H31: =IFERROR(__xludf.DUMMYFUNCTION("""COMPUTED_VALUE"""),"L") -> L
A32: =IFERROR(__xludf.DUMMYFUNCTION("""COMPUTED_VALUE"""),7640162323161) -> 7640162323161 | B32: =IFERROR(__xludf.DUMMYFUNCTION("""COMPUTED_VALUE"""),"МПНТО №100 19х72mm ТКАНЕВ") -> МПНТО №100 19х72mm ТКАНЕВ | C32: =IFERROR(__xludf.DUMMYFUNCTION("""COMPUTED_VALUE"""),"МЕДИЦИНСКИЙ ПЛАСТЫРЬ НА ТКАНЕВОЙ ОСНОВЕ (19mm х 72mm) №100") -> МЕДИЦИНСКИЙ ПЛАСТЫРЬ НА ТКАНЕВОЙ ОСНОВЕ (19mm х 72mm) №100 | D32: =IFERROR(__xludf.DUMMYFUNCTION("""COMPUTED_VALUE"""),"МЕДИЦИНСКИЙ ПЛАСТЫРЬ НА ТКАНЕВОЙ ОСНОВЕ «ТМ Dr.Frei» №100 (19mm х 72mm) /ш/к 7640162323161") -> МЕДИЦИНСКИЙ ПЛАСТЫРЬ НА ТКАНЕВОЙ ОСНОВЕ «ТМ Dr.Frei» №100 (19mm х 72mm) /ш/к 7640162323161 | E32: =IFERROR(__xludf.DUMMYFUNCTION("""COMPUTED_VALUE"""),"шт") -> шт | F32: =IFERROR(__xludf.DUMMYFUNCTION("""COMPUTED_VALUE"""),"AST00000615") -> AST00000615 | G32: =IFERROR(__xludf.DUMMYFUNCTION("""COMPUTED_VALUE"""),7640162323161) -> 7640162323161 | H32: =IFERROR(__xludf.DUMMYFUNCTION("""COMPUTED_VALUE"""),"M") -> M
A33: =IFERROR(__xludf.DUMMYFUNCTION("""COMPUTED_VALUE"""),7640162323192) -> 7640162323192 | B33: =IFERROR(__xludf.DUMMYFUNCTION("""COMPUTED_VALUE"""),"МХБПВР 5m x 1,25cm ТКАНЕВ") -> МХБПВР 5m x 1,25cm ТКАНЕВ | C33: =IFERROR(__xludf.DUMMYFUNCTION("""COMPUTED_VALUE"""),"МЕДИЦИНСКИЙ ХЛОПЧАТОБУМАЖНЫЙ ПЛАСТЫРЬ В РУЛОНЕ (5m x 1,25cm)") -> МЕДИЦИНСКИЙ ХЛОПЧАТОБУМАЖНЫЙ ПЛАСТЫРЬ В РУЛОНЕ (5m x 1,25cm) | D33: =IFERROR(__xludf.DUMMYFUNCTION("""COMPUTED_VALUE"""),"МЕДИЦИНСКИЙ ХЛОПЧАТОБУМАЖНЫЙ ПЛАСТЫРЬ В РУЛОНЕ ТМ Dr.Frei (5m x 1,25cm) / ш/к 7640162323192") -> МЕДИЦИНСКИЙ ХЛОПЧАТОБУМАЖНЫЙ ПЛАСТЫРЬ В РУЛОНЕ ТМ Dr.Frei (5m x 1,25cm) / ш/к 7640162323192 | E33: =IFERROR(__xludf.DUMMYFUNCTION("""COMPUTED_VALUE"""),"шт") -> шт | F33: =IFERROR(__xludf.DUMMYFUNCTION("""COMPUTED_VALUE"""),"AST00000622") -> AST00000622 | G33: =IFERROR(__xludf.DUMMYFUNCTION("""COMPUTED_VALUE"""),7640162323192) -> 7640162323192 | H33: =IFERROR(__xludf.DUMMYFUNCTION("""COMPUTED_VALUE"""),"S") -> S
A34: =IFERROR(__xludf.DUMMYFUNCTION("""COMPUTED_VALUE"""),7640162323208) -> 7640162323208 | B34: =IFERROR(__xludf.DUMMYFUNCTION("""COMPUTED_VALUE"""),"МХБПВР 5m x 2,5cm ТКАНЕВЫ") -> МХБПВР 5m x 2,5cm ТКАНЕВЫ | C34: =IFERROR(__xludf.DUMMYFUNCTION("""COMPUTED_VALUE"""),"МЕДИЦИНСКИЙ ХЛОПЧАТОБУМАЖНЫЙ ПЛАСТЫРЬ В РУЛОНЕ (5m x 2,5cm)") -> МЕДИЦИНСКИЙ ХЛОПЧАТОБУМАЖНЫЙ ПЛАСТЫРЬ В РУЛОНЕ (5m x 2,5cm) | D34: =IFERROR(__xludf.DUMMYFUNCTION("""COMPUTED_VALUE"""),"МЕДИЦИНСКИЙ ХЛОПЧАТОБУМАЖНЫЙ ПЛАСТЫРЬ В РУЛОНЕ ТМ Dr.Frei (5m x 2,5cm) / ш/к 7640162323208") -> МЕДИЦИНСКИЙ ХЛОПЧАТОБУМАЖНЫЙ ПЛАСТЫРЬ В РУЛОНЕ ТМ Dr.Frei (5m x 2,5cm) / ш/к 7640162323208 | E34: =IFERROR(__xludf.DUMMYFUNCTION("""COMPUTED_VALUE"""),"шт") -> шт | F34: =IFERROR(__xludf.DUMMYFUNCTION("""COMPUTED_VALUE"""),"AST00000623") -> AST00000623 | G34: =IFERROR(__xludf.DUMMYFUNCTION("""COMPUTED_VALUE"""),7640162323208) -> 7640162323208 | H34: =IFERROR(__xludf.DUMMYFUNCTION("""COMPUTED_VALUE"""),"XL") -> XL
A35: =IFERROR(__xludf.DUMMYFUNCTION("""COMPUTED_VALUE"""),7640162323130) -> 7640162323130 | B35: =IFERROR(__xludf.DUMMYFUNCTION("""COMPUTED_VALUE"""),"ПДД №20") -> ПДД №20 | C35: =IFERROR(__xludf.DUMMYFUNCTION("""COMPUTED_VALUE"""),"ПЛАСТЫРИ ДЛЯ ДЕТЕЙ (19mm х 72mm) №20") -> ПЛАСТЫРИ ДЛЯ ДЕТЕЙ (19mm х 72mm) №20 | D35: =IFERROR(__xludf.DUMMYFUNCTION("""COMPUTED_VALUE"""),"ПЛАСТЫРИ ДЛЯ ДЕТЕЙ «ТМ Dr.Frei» №20 /ш/к 7640162323130") -> ПЛАСТЫРИ ДЛЯ ДЕТЕЙ «ТМ Dr.Frei» №20 /ш/к 7640162323130 | E35: =IFERROR(__xludf.DUMMYFUNCTION("""COMPUTED_VALUE"""),"шт") -> шт | F35: =IFERROR(__xludf.DUMMYFUNCTION("""COMPUTED_VALUE"""),"AST00000620") -> AST00000620 | G35: =IFERROR(__xludf.DUMMYFUNCTION("""COMPUTED_VALUE"""),7640162323130) -> 7640162323130 | H35: =IFERROR(__xludf.DUMMYFUNCTION("""COMPUTED_VALUE"""),"XXL") -> XXL
A36: =IFERROR(__xludf.DUMMYFUNCTION("""COMPUTED_VALUE"""),"Hometest") -> Hometest | H36: =IFERROR(__xludf.DUMMYFUNCTION("""COMPUTED_VALUE"""),"XXXL") -> XXXL
A37: =IFERROR(__xludf.DUMMYFUNCTION("""COMPUTED_VALUE"""),6941298300042) -> 6941298300042 | B37: =IFERROR(__xludf.DUMMYFUNCTION("""COMPUTED_VALUE"""),"HCG110/3№1") -> HCG110/3№1 | C37: =IFERROR(__xludf.DUMMYFUNCTION("""COMPUTED_VALUE"""),"Экспресс-Тест (полоска) на беременность 3 мм №1") -> Экспресс-Тест (полоска) на беременность 3 мм №1 | D37: =IFERROR(__xludf.DUMMYFUNCTION("""COMPUTED_VALUE"""),"Экспресс-тест (полоска) на беременность 3мм. №1 ш/к 6941298300042") -> Экспресс-тест (полоска) на беременность 3мм. №1 ш/к 6941298300042 | E37: =IFERROR(__xludf.DUMMYFUNCTION("""COMPUTED_VALUE"""),"упак.") -> упак. | F37: =IFERROR(__xludf.DUMMYFUNCTION("""COMPUTED_VALUE"""),"ТСН00003") -> ТСН00003 | G37: =IFERROR(__xludf.DUMMYFUNCTION("""COMPUTED_VALUE"""),6941298300042) -> 6941298300042 | H37: =IFERROR(__xludf.DUMMYFUNCTION("""COMPUTED_VALUE"""),"XXXXL") -> XXXXL
A38: =IFERROR(__xludf.DUMMYFUNCTION("""COMPUTED_VALUE"""),6941298300059) -> 6941298300059 | B38: =IFERROR(__xludf.DUMMYFUNCTION("""COMPUTED_VALUE"""),"HCG110/3№2") -> HCG110/3№2 | C38: =IFERROR(__xludf.DUMMYFUNCTION("""COMPUTED_VALUE"""),"Экспресс-Тест (полоска) на беременность 3 мм №2 ПДВ") -> Экспресс-Тест (полоска) на беременность 3 мм №2 ПДВ | D38: =IFERROR(__xludf.DUMMYFUNCTION("""COMPUTED_VALUE"""),"Экспресс-тест (полоска) на беременность 3мм. №2 ш/к 6941298300059") -> Экспресс-тест (полоска) на беременность 3мм. №2 ш/к 6941298300059 | E38: =IFERROR(__xludf.DUMMYFUNCTION("""COMPUTED_VALUE"""),"упак.") -> упак. | F38: =IFERROR(__xludf.DUMMYFUNCTION("""COMPUTED_VALUE"""),"ТСН00004") -> ТСН00004 | G38: =IFERROR(__xludf.DUMMYFUNCTION("""COMPUTED_VALUE"""),6941298300059) -> 6941298300059 | H38: =IFERROR(__xludf.DUMMYFUNCTION("""COMPUTED_VALUE"""),"L") -> L
A39: =IFERROR(__xludf.DUMMYFUNCTION("""COMPUTED_VALUE"""),6941298300035) -> 6941298300035 | B39: =IFERROR(__xludf.DUMMYFUNCTION("""COMPUTED_VALUE"""),"HCG112") -> HCG112 | C39: =IFERROR(__xludf.DUMMYFUNCTION("""COMPUTED_VALUE"""),"Экспресс-Тест (струйный) на беременность") -> Экспресс-Тест (струйный) на беременность | D39: =IFERROR(__xludf.DUMMYFUNCTION("""COMPUTED_VALUE"""),"Экспресс-тест (струйный) на беременность ш/к 6941298300035") -> Экспресс-тест (струйный) на беременность ш/к 6941298300035 | E39: =IFERROR(__xludf.DUMMYFUNCTION("""COMPUTED_VALUE"""),"упак.") -> упак. | F39: =IFERROR(__xludf.DUMMYFUNCTION("""COMPUTED_VALUE"""),"ТСН00007") -> ТСН00007 | G39: =IFERROR(__xludf.DUMMYFUNCTION("""COMPUTED_VALUE"""),6941298300035) -> 6941298300035 | H39: =IFERROR(__xludf.DUMMYFUNCTION("""COMPUTED_VALUE"""),"M") -> M
A40: =IFERROR(__xludf.DUMMYFUNCTION("""COMPUTED_VALUE"""),77173) -> 77173 | B40: =IFERROR(__xludf.DUMMYFUNCTION("""COMPUTED_VALUE"""),"HomeTest№1 Акция") -> HomeTest№1 Акция | C40: =IFERROR(__xludf.DUMMYFUNCTION("""COMPUTED_VALUE"""),"HomeTest №1 Акция по 1тг") -> HomeTest №1 Акция по 1тг | D40: =IFERROR(__xludf.DUMMYFUNCTION("""COMPUTED_VALUE"""),"Экспресс-тест HomeTest (полоска) для ранней диагностики беременности 3мм №1 ш/к 6941298300042 Акция по 1тг") -> Экспресс-тест HomeTest (полоска) для ранней диагностики беременности 3мм №1 ш/к 6941298300042 Акция по 1тг | E40: =IFERROR(__xludf.DUMMYFUNCTION("""COMPUTED_VALUE"""),"упак.") -> упак. | F40: =IFERROR(__xludf.DUMMYFUNCTION("""COMPUTED_VALUE"""),"AST00000388") -> AST00000388 | G40: =IFERROR(__xludf.DUMMYFUNCTION("""COMPUTED_VALUE"""),77173) -> 77173 | H40: =IFERROR(__xludf.DUMMYFUNCTION("""COMPUTED_VALUE"""),"S") -> S
...

Sheet LOT
A1: Краткое наименование | B1: № сертификата | C1: Действителен | D1: LOT
A2: =IFERROR(__xludf.DUMMYFUNCTION("IMPORTRANGE(""1qptHSRGmBGpZ2a-3Sl03VuQVlQVTlolfenhhSjzQQ7U/edit#gid=490982906"",""LOT!A2:H"")"),"Бандаж на шейный отдел позвоночника мягкой фиксацией 1001 I(S) (Болгария)") -> Бандаж на шейный отдел позвоночника мягкой фиксацией 1001 I(S) (Болгария) | B2: =IFERROR(__xludf.DUMMYFUNCTION("""COMPUTED_VALUE"""),"KZ.7100.01.01.00501816") -> KZ.7100.01.01.00501816 | C2: =IFERROR(__xludf.DUMMYFUNCTION("""COMPUTED_VALUE"""),"Действителен до 01.03.2022") -> Действителен до 01.03.2022 | D2: =IFERROR(__xludf.DUMMYFUNCTION("""COMPUTED_VALUE"""),"0217069KZ42") -> 0217069KZ42 | E2: =IFERROR(__xludf.DUMMYFUNCTION("""COMPUTED_VALUE"""),"годен до 01 03 2022 г.") -> годен до 01 03 2022 г. | F2: =IFERROR(__xludf.DUMMYFUNCTION("""COMPUTED_VALUE"""),"Бандаж на шейный отдел позвоночника мягкой фиксацией 1001 I(S) (Болгария) - 0217069KZ42") -> Бандаж на шейный отдел позвоночника мягкой фиксацией 1001 I(S) (Болгария) - 0217069KZ42 | G2: =IFERROR(__xludf.DUMMYFUNCTION("""COMPUTED_VALUE"""),"KZ.7100.01.01.00501816 / Действителен до 01.03.2022 / 0217069KZ42 / годен до 01 03 2022 г.") -> KZ.7100.01.01.00501816 / Действителен до 01.03.2022 / 0217069KZ42 / годен до 01 03 2022 г. | H2: =IFERROR(__xludf.DUMMYFUNCTION("""COMPUTED_VALUE"""),"Бандаж на шейный отдел позвоночника мягкой фиксацией 1001 I(S) (Болгария) KZ.7100.01.01.00501816 / Действителен до 01.03.2022 / 0217069KZ42 / годен до 01 03 2022 г.") -> Бандаж на шейный отдел позвоночника мягкой фиксацией 1001 I(S) (Болгария) KZ.7100.01.01.00501816 / Действителен до 01.03.2022 / 0217069KZ42 / годен до 01 03 2022 г.
A3: =IFERROR(__xludf.DUMMYFUNCTION("""COMPUTED_VALUE"""),"Бандаж на шейный отдел позвоночника мягкой фиксацией 1001 II(M) (Болгария)") -> Бандаж на шейный отдел позвоночника мягкой фиксацией 1001 II(M) (Болгария) | B3: =IFERROR(__xludf.DUMMYFUNCTION("""COMPUTED_VALUE"""),"KZ.7100.01.01.00501816") -> KZ.7100.01.01.00501816 | C3: =IFERROR(__xludf.DUMMYFUNCTION("""COMPUTED_VALUE"""),"Действителен до 01.03.2022") -> Действителен до 01.03.2022 | D3: =IFERROR(__xludf.DUMMYFUNCTION("""COMPUTED_VALUE"""),"0217069KZ42") -> 0217069KZ42 | E3: =IFERROR(__xludf.DUMMYFUNCTION("""COMPUTED_VALUE"""),"годен до 01 03 2022 г.") -> годен до 01 03 2022 г. | F3: =IFERROR(__xludf.DUMMYFUNCTION("""COMPUTED_VALUE"""),"Бандаж на шейный отдел позвоночника мягкой фиксацией 1001 II(M) (Болгария) - 0217069KZ42") -> Бандаж на шейный отдел позвоночника мягкой фиксацией 1001 II(M) (Болгария) - 0217069KZ42 | G3: =IFERROR(__xludf.DUMMYFUNCTION("""COMPUTED_VALUE"""),"KZ.7100.01.01.00501816 / Действителен до 01.03.2022 / 0217069KZ42 / годен до 01 03 2022 г.") -> KZ.7100.01.01.00501816 / Действителен до 01.03.2022 / 0217069KZ42 / годен до 01 03 2022 г. | H3: =IFERROR(__xludf.DUMMYFUNCTION("""COMPUTED_VALUE"""),"Бандаж на шейный отдел позвоночника мягкой фиксацией 1001 II(M) (Болгария) KZ.7100.01.01.00501816 / Действителен до 01.03.2022 / 0217069KZ42 / годен до 01 03 2022 г.") -> Бандаж на шейный отдел позвоночника мягкой фиксацией 1001 II(M) (Болгария) KZ.7100.01.01.00501816 / Действителен до 01.03.2022 / 0217069KZ42 / годен до 01 03 2022 г.
A4: =IFERROR(__xludf.DUMMYFUNCTION("""COMPUTED_VALUE"""),"Бандаж на шейный отдел позвоночника мягкой фиксацией 1001 III(L) (Болгария)") -> Бандаж на шейный отдел позвоночника мягкой фиксацией 1001 III(L) (Болгария) | B4: =IFERROR(__xludf.DUMMYFUNCTION("""COMPUTED_VALUE"""),"KZ.7100.01.01.00501816") -> KZ.7100.01.01.00501816 | C4: =IFERROR(__xludf.DUMMYFUNCTION("""COMPUTED_VALUE"""),"Действителен до 01.03.2022") -> Действителен до 01.03.2022 | D4: =IFERROR(__xludf.DUMMYFUNCTION("""COMPUTED_VALUE"""),"0217069KZ42") -> 0217069KZ42 | E4: =IFERROR(__xludf.DUMMYFUNCTION("""COMPUTED_VALUE"""),"годен до 01 03 2022 г.") -> годен до 01 03 2022 г. | F4: =IFERROR(__xludf.DUMMYFUNCTION("""COMPUTED_VALUE"""),"Бандаж на шейный отдел позвоночника мягкой фиксацией 1001 III(L) (Болгария) - 0217069KZ42") -> Бандаж на шейный отдел позвоночника мягкой фиксацией 1001 III(L) (Болгария) - 0217069KZ42 | G4: =IFERROR(__xludf.DUMMYFUNCTION("""COMPUTED_VALUE"""),"KZ.7100.01.01.00501816 / Действителен до 01.03.2022 / 0217069KZ42 / годен до 01 03 2022 г.") -> KZ.7100.01.01.00501816 / Действителен до 01.03.2022 / 0217069KZ42 / годен до 01 03 2022 г. | H4: =IFERROR(__xludf.DUMMYFUNCTION("""COMPUTED_VALUE"""),"Бандаж на шейный отдел позвоночника мягкой фиксацией 1001 III(L) (Болгария) KZ.7100.01.01.00501816 / Действителен до 01.03.2022 / 0217069KZ42 / годен до 01 03 2022 г.") -> Бандаж на шейный отдел позвоночника мягкой фиксацией 1001 III(L) (Болгария) KZ.7100.01.01.00501816 / Действителен до 01.03.2022 / 0217069KZ42 / годен до 01 03 2022 г.
A5: =IFERROR(__xludf.DUMMYFUNCTION("""COMPUTED_VALUE"""),"Бандаж на шейный отдел позвоночника мягкой фиксацией 1001 I(S) (Болгария)") -> Бандаж на шейный отдел позвоночника мягкой фиксацией 1001 I(S) (Болгария) | B5: =IFERROR(__xludf.DUMMYFUNCTION("""COMPUTED_VALUE"""),"KZ.7100.01.01.00502589") -> KZ.7100.01.01.00502589 | C5: =IFERROR(__xludf.DUMMYFUNCTION("""COMPUTED_VALUE"""),"Действителен до 05.03.2022") -> Действителен до 05.03.2022 | D5: =IFERROR(__xludf.DUMMYFUNCTION("""COMPUTED_VALUE"""),"0417016KZ11") -> 0417016KZ11 | E5: =IFERROR(__xludf.DUMMYFUNCTION("""COMPUTED_VALUE"""),"годен до 05.03.2022") -> годен до 05.03.2022 | F5: =IFERROR(__xludf.DUMMYFUNCTION("""COMPUTED_VALUE"""),"Бандаж на шейный отдел позвоночника мягкой фиксацией 1001 I(S) (Болгария) - 0417016KZ11") -> Бандаж на шейный отдел позвоночника мягкой фиксацией 1001 I(S) (Болгария) - 0417016KZ11 | G5: =IFERROR(__xludf.DUMMYFUNCTION("""COMPUTED_VALUE"""),"KZ.7100.01.01.00502589 / Действителен до 05.03.2022 / 0417016KZ11 / годен до 05.03.2022") -> KZ.7100.01.01.00502589 / Действителен до 05.03.2022 / 0417016KZ11 / годен до 05.03.2022 | H5: =IFERROR(__xludf.DUMMYFUNCTION("""COMPUTED_VALUE"""),"Бандаж на шейный отдел позвоночника мягкой фиксацией 1001 I(S) (Болгария) KZ.7100.01.01.00502589 / Действителен до 05.03.2022 / 0417016KZ11 / годен до 05.03.2022") -> Бандаж на шейный отдел позвоночника мягкой фиксацией 1001 I(S) (Болгария) KZ.7100.01.01.00502589 / Действителен до 05.03.2022 / 0417016KZ11 / годен до 05.03.2022
A6: =IFERROR(__xludf.DUMMYFUNCTION("""COMPUTED_VALUE"""),"Бандаж на шейный отдел позвоночника мягкой фиксацией 1001 II(M) (Болгария)") -> Бандаж на шейный отдел позвоночника мягкой фиксацией 1001 II(M) (Болгария) | B6: =IFERROR(__xludf.DUMMYFUNCTION("""COMPUTED_VALUE"""),"KZ.7100.01.01.00502589") -> KZ.7100.01.01.00502589 | C6: =IFERROR(__xludf.DUMMYFUNCTION("""COMPUTED_VALUE"""),"Действителен до 05.03.2022") -> Действителен до 05.03.2022 | D6: =IFERROR(__xludf.DUMMYFUNCTION("""COMPUTED_VALUE"""),"0417016KZ11") -> 0417016KZ11 | E6: =IFERROR(__xludf.DUMMYFUNCTION("""COMPUTED_VALUE"""),"годен до 05.03.2022") -> годен до 05.03.2022 | F6: =IFERROR(__xludf.DUMMYFUNCTION("""COMPUTED_VALUE"""),"Бандаж на шейный отдел позвоночника мягкой фиксацией 1001 II(M) (Болгария) - 0417016KZ11") -> Бандаж на шейный отдел позвоночника мягкой фиксацией 1001 II(M) (Болгария) - 0417016KZ11 | G6: =IFERROR(__xludf.DUMMYFUNCTION("""COMPUTED_VALUE"""),"KZ.7100.01.01.00502589 / Действителен до 05.03.2022 / 0417016KZ11 / годен до 05.03.2022") -> KZ.7100.01.01.00502589 / Действителен до 05.03.2022 / 0417016KZ11 / годен до 05.03.2022 | H6: =IFERROR(__xludf.DUMMYFUNCTION("""COMPUTED_VALUE"""),"Бандаж на шейный отдел позвоночника мягкой фиксацией 1001 II(M) (Болгария) KZ.7100.01.01.00502589 / Действителен до 05.03.2022 / 0417016KZ11 / годен до 05.03.2022") -> Бандаж на шейный отдел позвоночника мягкой фиксацией 1001 II(M) (Болгария) KZ.7100.01.01.00502589 / Действителен до 05.03.2022 / 0417016KZ11 / годен до 05.03.2022
A7: =IFERROR(__xludf.DUMMYFUNCTION("""COMPUTED_VALUE"""),"Бандаж на шейный отдел позвоночника мягкой фиксацией 1001 III(L) (Болгария)") -> Бандаж на шейный отдел позвоночника мягкой фиксацией 1001 III(L) (Болгария) | B7: =IFERROR(__xludf.DUMMYFUNCTION("""COMPUTED_VALUE"""),"KZ.7100.01.01.00502589") -> KZ.7100.01.01.00502589 | C7: =IFERROR(__xludf.DUMMYFUNCTION("""COMPUTED_VALUE"""),"Действителен до 05.03.2022") -> Действителен до 05.03.2022 | D7: =IFERROR(__xludf.DUMMYFUNCTION("""COMPUTED_VALUE"""),"0417016KZ11") -> 0417016KZ11 | E7: =IFERROR(__xludf.DUMMYFUNCTION("""COMPUTED_VALUE"""),"годен до 05.03.2022") -> годен до 05.03.2022 | F7: =IFERROR(__xludf.DUMMYFUNCTION("""COMPUTED_VALUE"""),"Бандаж на шейный отдел позвоночника мягкой фиксацией 1001 III(L) (Болгария) - 0417016KZ11") -> Бандаж на шейный отдел позвоночника мягкой фиксацией 1001 III(L) (Болгария) - 0417016KZ11 | G7: =IFERROR(__xludf.DUMMYFUNCTION("""COMPUTED_VALUE"""),"KZ.7100.01.01.00502589 / Действителен до 05.03.2022 / 0417016KZ11 / годен до 05.03.2022") -> KZ.7100.01.01.00502589 / Действителен до 05.03.2022 / 0417016KZ11 / годен до 05.03.2022 | H7: =IFERROR(__xludf.DUMMYFUNCTION("""COMPUTED_VALUE"""),"Бандаж на шейный отдел позвоночника мягкой фиксацией 1001 III(L) (Болгария) KZ.7100.01.01.00502589 / Действителен до 05.03.2022 / 0417016KZ11 / годен до 05.03.2022") -> Бандаж на шейный отдел позвоночника мягкой фиксацией 1001 III(L) (Болгария) KZ.7100.01.01.00502589 / Действителен до 05.03.2022 / 0417016KZ11 / годен до 05.03.2022
A8: =IFERROR(__xludf.DUMMYFUNCTION("""COMPUTED_VALUE"""),"Бандаж на шейный отдел позвоночника мягкой фиксацией 1001 I(S) (Болгария)") -> Бандаж на шейный отдел позвоночника мягкой фиксацией 1001 I(S) (Болгария) | B8: =IFERROR(__xludf.DUMMYFUNCTION("""COMPUTED_VALUE"""),"KZ.7100.01.01.00503695") -> KZ.7100.01.01.00503695 | C8: =IFERROR(__xludf.DUMMYFUNCTION("""COMPUTED_VALUE"""),"Действителен до 21.06.2022") -> Действителен до 21.06.2022 | D8: =IFERROR(__xludf.DUMMYFUNCTION("""COMPUTED_VALUE"""),"0617041KZ30") -> 0617041KZ30 | E8: =IFERROR(__xludf.DUMMYFUNCTION("""COMPUTED_VALUE"""),"годен до 21.06.2022") -> годен до 21.06.2022 | F8: =IFERROR(__xludf.DUMMYFUNCTION("""COMPUTED_VALUE"""),"Бандаж на шейный отдел позвоночника мягкой фиксацией 1001 I(S) (Болгария) - 0617041KZ30") -> Бандаж на шейный отдел позвоночника мягкой фиксацией 1001 I(S) (Болгария) - 0617041KZ30 | G8: =IFERROR(__xludf.DUMMYFUNCTION("""COMPUTED_VALUE"""),"KZ.7100.01.01.00503695 / Действителен до 21.06.2022 / 0617041KZ30 / годен до 21.06.2022") -> KZ.7100.01.01.00503695 / Действителен до 21.06.2022 / 0617041KZ30 / годен до 21.06.2022 | H8: =IFERROR(__xludf.DUMMYFUNCTION("""COMPUTED_VALUE"""),"Бандаж на шейный отдел позвоночника мягкой фиксацией 1001 I(S) (Болгария) KZ.7100.01.01.00503695 / Действителен до 21.06.2022 / 0617041KZ30 / годен до 21.06.2022") -> Бандаж на шейный отдел позвоночника мягкой фиксацией 1001 I(S) (Болгария) KZ.7100.01.01.00503695 / Действителен до 21.06.2022 / 0617041KZ30 / годен до 21.06.2022
A9: =IFERROR(__xludf.DUMMYFUNCTION("""COMPUTED_VALUE"""),"Бандаж на шейный отдел позвоночника мягкой фиксацией 1001 II(M) (Болгария)") -> Бандаж на шейный отдел позвоночника мягкой фиксацией 1001 II(M) (Болгария) | B9: =IFERROR(__xludf.DUMMYFUNCTION("""COMPUTED_VALUE"""),"KZ.7100.01.01.00503695") -> KZ.7100.01.01.00503695 | C9: =IFERROR(__xludf.DUMMYFUNCTION("""COMPUTED_VALUE"""),"Действителен до 21.06.2022") -> Действителен до 21.06.2022 | D9: =IFERROR(__xludf.DUMMYFUNCTION("""COMPUTED_VALUE"""),"0617041KZ30") -> 0617041KZ30 | E9: =IFERROR(__xludf.DUMMYFUNCTION("""COMPUTED_VALUE"""),"годен до 21.06.2022") -> годен до 21.06.2022 | F9: =IFERROR(__xludf.DUMMYFUNCTION("""COMPUTED_VALUE"""),"Бандаж на шейный отдел позвоночника мягкой фиксацией 1001 II(M) (Болгария) - 0617041KZ30") -> Бандаж на шейный отдел позвоночника мягкой фиксацией 1001 II(M) (Болгария) - 0617041KZ30 | G9: =IFERROR(__xludf.DUMMYFUNCTION("""COMPUTED_VALUE"""),"KZ.7100.01.01.00503695 / Действителен до 21.06.2022 / 0617041KZ30 / годен до 21.06.2022") -> KZ.7100.01.01.00503695 / Действителен до 21.06.2022 / 0617041KZ30 / годен до 21.06.2022 | H9: =IFERROR(__xludf.DUMMYFUNCTION("""COMPUTED_VALUE"""),"Бандаж на шейный отдел позвоночника мягкой фиксацией 1001 II(M) (Болгария) KZ.7100.01.01.00503695 / Действителен до 21.06.2022 / 0617041KZ30 / годен до 21.06.2022") -> Бандаж на шейный отдел позвоночника мягкой фиксацией 1001 II(M) (Болгария) KZ.7100.01.01.00503695 / Действителен до 21.06.2022 / 0617041KZ30 / годен до 21.06.2022
A10: =IFERROR(__xludf.DUMMYFUNCTION("""COMPUTED_VALUE"""),"Бандаж на шейный отдел позвоночника мягкой фиксацией 1001 III(L) (Болгария)") -> Бандаж на шейный отдел позвоночника мягкой фиксацией 1001 III(L) (Болгария) | B10: =IFERROR(__xludf.DUMMYFUNCTION("""COMPUTED_VALUE"""),"KZ.7100.01.01.00503695") -> KZ.7100.01.01.00503695 | C10: =IFERROR(__xludf.DUMMYFUNCTION("""COMPUTED_VALUE"""),"Действителен до 21.06.2022") -> Действителен до 21.06.2022 | D10: =IFERROR(__xludf.DUMMYFUNCTION("""COMPUTED_VALUE"""),"0617041KZ30") -> 0617041KZ30 | E10: =IFERROR(__xludf.DUMMYFUNCTION("""COMPUTED_VALUE"""),"годен до 21.06.2022") -> годен до 21.06.2022 | F10: =IFERROR(__xludf.DUMMYFUNCTION("""COMPUTED_VALUE"""),"Бандаж на шейный отдел позвоночника мягкой фиксацией 1001 III(L) (Болгария) - 0617041KZ30") -> Бандаж на шейный отдел позвоночника мягкой фиксацией 1001 III(L) (Болгария) - 0617041KZ30 | G10: =IFERROR(__xludf.DUMMYFUNCTION("""COMPUTED_VALUE"""),"KZ.7100.01.01.00503695 / Действителен до 21.06.2022 / 0617041KZ30 / годен до 21.06.2022") -> KZ.7100.01.01.00503695 / Действителен до 21.06.2022 / 0617041KZ30 / годен до 21.06.2022 | H10: =IFERROR(__xludf.DUMMYFUNCTION("""COMPUTED_VALUE"""),"Бандаж на шейный отдел позвоночника мягкой фиксацией 1001 III(L) (Болгария) KZ.7100.01.01.00503695 / Действителен до 21.06.2022 / 0617041KZ30 / годен до 21.06.2022") -> Бандаж на шейный отдел позвоночника мягкой фиксацией 1001 III(L) (Болгария) KZ.7100.01.01.00503695 / Действителен до 21.06.2022 / 0617041KZ30 / годен до 21.06.2022
A11: =IFERROR(__xludf.DUMMYFUNCTION("""COMPUTED_VALUE"""),"Бандаж на шейный отдел позвоночника мягкой фиксацией 1001 I(S) (Болгария)") -> Бандаж на шейный отдел позвоночника мягкой фиксацией 1001 I(S) (Болгария) | B11: =IFERROR(__xludf.DUMMYFUNCTION("""COMPUTED_VALUE"""),"KZ.7100.01.01.00506598") -> KZ.7100.01.01.00506598 | C11: =IFERROR(__xludf.DUMMYFUNCTION("""COMPUTED_VALUE"""),"Действителен до 15.11.2022") -> Действителен до 15.11.2022 | D11: =IFERROR(__xludf.DUMMYFUNCTION("""COMPUTED_VALUE"""),"1117047KZ59") -> 1117047KZ59 | E11: =IFERROR(__xludf.DUMMYFUNCTION("""COMPUTED_VALUE"""),"годен до 15.11.2022") -> годен до 15.11.2022 | F11: =IFERROR(__xludf.DUMMYFUNCTION("""COMPUTED_VALUE"""),"Бандаж на шейный отдел позвоночника мягкой фиксацией 1001 I(S) (Болгария) - 1117047KZ59") -> Бандаж на шейный отдел позвоночника мягкой фиксацией 1001 I(S) (Болгария) - 1117047KZ59 | G11: =IFERROR(__xludf.DUMMYFUNCTION("""COMPUTED_VALUE"""),"KZ.7100.01.01.00506598 / Действителен до 15.11.2022 / 1117047KZ59 / годен до 15.11.2022") -> KZ.7100.01.01.00506598 / Действителен до 15.11.2022 / 1117047KZ59 / годен до 15.11.2022 | H11: =IFERROR(__xludf.DUMMYFUNCTION("""COMPUTED_VALUE"""),"Бандаж на шейный отдел позвоночника мягкой фиксацией 1001 I(S) (Болгария) KZ.7100.01.01.00506598 / Действителен до 15.11.2022 / 1117047KZ59 / годен до 15.11.2022") -> Бандаж на шейный отдел позвоночника мягкой фиксацией 1001 I(S) (Болгария) KZ.7100.01.01.00506598 / Действителен до 15.11.2022 / 1117047KZ59 / годен до 15.11.2022
A12: =IFERROR(__xludf.DUMMYFUNCTION("""COMPUTED_VALUE"""),"Бандаж на шейный отдел позвоночника мягкой фиксацией 1001 II(M) (Болгария)") -> Бандаж на шейный отдел позвоночника мягкой фиксацией 1001 II(M) (Болгария) | B12: =IFERROR(__xludf.DUMMYFUNCTION("""COMPUTED_VALUE"""),"KZ.7100.01.01.00506598") -> KZ.7100.01.01.00506598 | C12: =IFERROR(__xludf.DUMMYFUNCTION("""COMPUTED_VALUE"""),"Действителен до 15.11.2022") -> Действителен до 15.11.2022 | D12: =IFERROR(__xludf.DUMMYFUNCTION("""COMPUTED_VALUE"""),"1117047KZ59") -> 1117047KZ59 | E12: =IFERROR(__xludf.DUMMYFUNCTION("""COMPUTED_VALUE"""),"годен до 15.11.2022") -> годен до 15.11.2022 | F12: =IFERROR(__xludf.DUMMYFUNCTION("""COMPUTED_VALUE"""),"Бандаж на шейный отдел позвоночника мягкой фиксацией 1001 II(M) (Болгария) - 1117047KZ59") -> Бандаж на шейный отдел позвоночника мягкой фиксацией 1001 II(M) (Болгария) - 1117047KZ59 | G12: =IFERROR(__xludf.DUMMYFUNCTION("""COMPUTED_VALUE"""),"KZ.7100.01.01.00506598 / Действителен до 15.11.2022 / 1117047KZ59 / годен до 15.11.2022") -> KZ.7100.01.01.00506598 / Действителен до 15.11.2022 / 1117047KZ59 / годен до 15.11.2022 | H12: =IFERROR(__xludf.DUMMYFUNCTION("""COMPUTED_VALUE"""),"Бандаж на шейный отдел позвоночника мягкой фиксацией 1001 II(M) (Болгария) KZ.7100.01.01.00506598 / Действителен до 15.11.2022 / 1117047KZ59 / годен до 15.11.2022") -> Бандаж на шейный отдел позвоночника мягкой фиксацией 1001 II(M) (Болгария) KZ.7100.01.01.00506598 / Действителен до 15.11.2022 / 1117047KZ59 / годен до 15.11.2022
A13: =IFERROR(__xludf.DUMMYFUNCTION("""COMPUTED_VALUE"""),"Бандаж на шейный отдел позвоночника мягкой фиксацией 1001 III(L) (Болгария)") -> Бандаж на шейный отдел позвоночника мягкой фиксацией 1001 III(L) (Болгария) | B13: =IFERROR(__xludf.DUMMYFUNCTION("""COMPUTED_VALUE"""),"KZ.7100.01.01.00506598") -> KZ.7100.01.01.00506598 | C13: =IFERROR(__xludf.DUMMYFUNCTION("""COMPUTED_VALUE"""),"Действителен до 15.11.2022") -> Действителен до 15.11.2022 | D13: =IFERROR(__xludf.DUMMYFUNCTION("""COMPUTED_VALUE"""),"1117047KZ59") -> 1117047KZ59 | E13: =IFERROR(__xludf.DUMMYFUNCTION("""COMPUTED_VALUE"""),"годен до 15.11.2022") -> годен до 15.11.2022 | F13: =IFERROR(__xludf.DUMMYFUNCTION("""COMPUTED_VALUE"""),"Бандаж на шейный отдел позвоночника мягкой фиксацией 1001 III(L) (Болгария) - 1117047KZ59") -> Бандаж на шейный отдел позвоночника мягкой фиксацией 1001 III(L) (Болгария) - 1117047KZ59 | G13: =IFERROR(__xludf.DUMMYFUNCTION("""COMPUTED_VALUE"""),"KZ.7100.01.01.00506598 / Действителен до 15.11.2022 / 1117047KZ59 / годен до 15.11.2022") -> KZ.7100.01.01.00506598 / Действителен до 15.11.2022 / 1117047KZ59 / годен до 15.11.2022 | H13: =IFERROR(__xludf.DUMMYFUNCTION("""COMPUTED_VALUE"""),"Бандаж на шейный отдел позвоночника мягкой фиксацией 1001 III(L) (Болгария) KZ.7100.01.01.00506598 / Действителен до 15.11.2022 / 1117047KZ59 / годен до 15.11.2022") -> Бандаж на шейный отдел позвоночника мягкой фиксацией 1001 III(L) (Болгария) KZ.7100.01.01.00506598 / Действителен до 15.11.2022 / 1117047KZ59 / годен до 15.11.2022
A14: =IFERROR(__xludf.DUMMYFUNCTION("""COMPUTED_VALUE"""),"Бандаж на шейный отдел позвоночника мягкой фиксацией 1001 I(S) (Болгария)") -> Бандаж на шейный отдел позвоночника мягкой фиксацией 1001 I(S) (Болгария) | B14: =IFERROR(__xludf.DUMMYFUNCTION("""COMPUTED_VALUE"""),"KZ.7700.02.01.00516915") -> KZ.7700.02.01.00516915 | C14: =IFERROR(__xludf.DUMMYFUNCTION("""COMPUTED_VALUE"""),"Действителен до 31.03.2023") -> Действителен до 31.03.2023 | D14: =IFERROR(__xludf.DUMMYFUNCTION("""COMPUTED_VALUE"""),"0318003KZ03") -> 0318003KZ03 | E14: =IFERROR(__xludf.DUMMYFUNCTION("""COMPUTED_VALUE"""),"годен до 31.03.2023") -> годен до 31.03.2023 | F14: =IFERROR(__xludf.DUMMYFUNCTION("""COMPUTED_VALUE"""),"Бандаж на шейный отдел позвоночника мягкой фиксацией 1001 I(S) (Болгария) - 0318003KZ03") -> Бандаж на шейный отдел позвоночника мягкой фиксацией 1001 I(S) (Болгария) - 0318003KZ03 | G14: =IFERROR(__xludf.DUMMYFUNCTION("""COMPUTED_VALUE"""),"KZ.7700.02.01.00516915 / Действителен до 31.03.2023 / 0318003KZ03 / годен до 31.03.2023") -> KZ.7700.02.01.00516915 / Действителен до 31.03.2023 / 0318003KZ03 / годен до 31.03.2023 | H14: =IFERROR(__xludf.DUMMYFUNCTION("""COMPUTED_VALUE"""),"Бандаж на шейный отдел позвоночника мягкой фиксацией 1001 I(S) (Болгария) KZ.7700.02.01.00516915 / Действителен до 31.03.2023 / 0318003KZ03 / годен до 31.03.2023") -> Бандаж на шейный отдел позвоночника мягкой фиксацией 1001 I(S) (Болгария) KZ.7700.02.01.00516915 / Действителен до 31.03.2023 / 0318003KZ03 / годен до 31.03.2023
A15: =IFERROR(__xludf.DUMMYFUNCTION("""COMPUTED_VALUE"""),"Бандаж на шейный отдел позвоночника мягкой фиксацией 1001 II(M) (Болгария)") -> Бандаж на шейный отдел позвоночника мягкой фиксацией 1001 II(M) (Болгария) | B15: =IFERROR(__xludf.DUMMYFUNCTION("""COMPUTED_VALUE"""),"KZ.7700.02.01.00516916") -> KZ.7700.02.01.00516916 | C15: =IFERROR(__xludf.DUMMYFUNCTION("""COMPUTED_VALUE"""),"Действителен до 31.03.2023") -> Действителен до 31.03.2023 | D15: =IFERROR(__xludf.DUMMYFUNCTION("""COMPUTED_VALUE"""),"0318003KZ03") -> 0318003KZ03 | E15: =IFERROR(__xludf.DUMMYFUNCTION("""COMPUTED_VALUE"""),"годен до 31.03.2023") -> годен до 31.03.2023 | F15: =IFERROR(__xludf.DUMMYFUNCTION("""COMPUTED_VALUE"""),"Бандаж на шейный отдел позвоночника мягкой фиксацией 1001 II(M) (Болгария) - 0318003KZ03") -> Бандаж на шейный отдел позвоночника мягкой фиксацией 1001 II(M) (Болгария) - 0318003KZ03 | G15: =IFERROR(__xludf.DUMMYFUNCTION("""COMPUTED_VALUE"""),"KZ.7700.02.01.00516916 / Действителен до 31.03.2023 / 0318003KZ03 / годен до 31.03.2023") -> KZ.7700.02.01.00516916 / Действителен до 31.03.2023 / 0318003KZ03 / годен до 31.03.2023 | H15: =IFERROR(__xludf.DUMMYFUNCTION("""COMPUTED_VALUE"""),"Бандаж на шейный отдел позвоночника мягкой фиксацией 1001 II(M) (Болгария) KZ.7700.02.01.00516916 / Действителен до 31.03.2023 / 0318003KZ03 / годен до 31.03.2023") -> Бандаж на шейный отдел позвоночника мягкой фиксацией 1001 II(M) (Болгария) KZ.7700.02.01.00516916 / Действителен до 31.03.2023 / 0318003KZ03 / годен до 31.03.2023
A16: =IFERROR(__xludf.DUMMYFUNCTION("""COMPUTED_VALUE"""),"Бандаж на шейный отдел позвоночника мягкой фиксацией 1001 III(L) (Болгария)") -> Бандаж на шейный отдел позвоночника мягкой фиксацией 1001 III(L) (Болгария) | B16: =IFERROR(__xludf.DUMMYFUNCTION("""COMPUTED_VALUE"""),"KZ.7700.02.01.00516914") -> KZ.7700.02.01.00516914 | C16: =IFERROR(__xludf.DUMMYFUNCTION("""COMPUTED_VALUE"""),"Действителен до 31.03.2023") -> Действителен до 31.03.2023 | D16: =IFERROR(__xludf.DUMMYFUNCTION("""COMPUTED_VALUE"""),"0318003KZ03") -> 0318003KZ03 | E16: =IFERROR(__xludf.DUMMYFUNCTION("""COMPUTED_VALUE"""),"годен до 31.03.2023") -> годен до 31.03.2023 | F16: =IFERROR(__xludf.DUMMYFUNCTION("""COMPUTED_VALUE"""),"Бандаж на шейный отдел позвоночника мягкой фиксацией 1001 III(L) (Болгария) - 0318003KZ03") -> Бандаж на шейный отдел позвоночника мягкой фиксацией 1001 III(L) (Болгария) - 0318003KZ03 | G16: =IFERROR(__xludf.DUMMYFUNCTION("""COMPUTED_VALUE"""),"KZ.7700.02.01.00516914 / Действителен до 31.03.2023 / 0318003KZ03 / годен до 31.03.2023") -> KZ.7700.02.01.00516914 / Действителен до 31.03.2023 / 0318003KZ03 / годен до 31.03.2023 | H16: =IFERROR(__xludf.DUMMYFUNCTION("""COMPUTED_VALUE"""),"Бандаж на шейный отдел позвоночника мягкой фиксацией 1001 III(L) (Болгария) KZ.7700.02.01.00516914 / Действителен до 31.03.2023 / 0318003KZ03 / годен до 31.03.2023") -> Бандаж на шейный отдел позвоночника мягкой фиксацией 1001 III(L) (Болгария) KZ.7700.02.01.00516914 / Действителен до 31.03.2023 / 0318003KZ03 / годен до 31.03.2023
A17: =IFERROR(__xludf.DUMMYFUNCTION("""COMPUTED_VALUE"""),"Бандаж на шейный отдел позвоночника мягкой фиксацией 1001 III(L) (Болгария)") -> Бандаж на шейный отдел позвоночника мягкой фиксацией 1001 III(L) (Болгария) | B17: =IFERROR(__xludf.DUMMYFUNCTION("""COMPUTED_VALUE"""),"KZ.7700.02.01.00726425") -> KZ.7700.02.01.00726425 | C17: =IFERROR(__xludf.DUMMYFUNCTION("""COMPUTED_VALUE"""),"Действителен до 15.02.2026") -> Действителен до 15.02.2026 | D17: =IFERROR(__xludf.DUMMYFUNCTION("""COMPUTED_VALUE"""),"0221174KZ174") -> 0221174KZ174 | E17: =IFERROR(__xludf.DUMMYFUNCTION("""COMPUTED_VALUE"""),"годен до 15.02.2026") -> годен до 15.02.2026 | F17: =IFERROR(__xludf.DUMMYFUNCTION("""COMPUTED_VALUE"""),"Бандаж на шейный отдел позвоночника мягкой фиксацией 1001 III(L) (Болгария) - 0221174KZ174") -> Бандаж на шейный отдел позвоночника мягкой фиксацией 1001 III(L) (Болгария) - 0221174KZ174 | G17: =IFERROR(__xludf.DUMMYFUNCTION("""COMPUTED_VALUE"""),"KZ.7700.02.01.00726425 / Действителен до 15.02.2026 / 0221174KZ174 / годен до 15.02.2026") -> KZ.7700.02.01.00726425 / Действителен до 15.02.2026 / 0221174KZ174 / годен до 15.02.2026 | H17: =IFERROR(__xludf.DUMMYFUNCTION("""COMPUTED_VALUE"""),"Бандаж на шейный отдел позвоночника мягкой фиксацией 1001 III(L) (Болгария) KZ.7700.02.01.00726425 / Действителен до 15.02.2026 / 0221174KZ174 / годен до 15.02.2026") -> Бандаж на шейный отдел позвоночника мягкой фиксацией 1001 III(L) (Болгария) KZ.7700.02.01.00726425 / Действителен до 15.02.2026 / 0221174KZ174 / годен до 15.02.2026
